Workbook

Sheet 表紙
A1: ECS Fargate の起動タイマー検討
A2: startPeriod / dependsOn / ALB の猶予期間
A3: 作成日 2026-10-12。同じ内容の詳しい説明は ecs-healthcheck-startperiod-alb-grace.md。このブックの灰色のセルが入力。白い数値の多くは「計算」シートの式。入力を変えると、バッファとタイムラインが追従する。
A5: この資料で決めたこと
A6: 項目 | B6: 推奨 | C6: 単位の意味 | D6: 直列にした場合 | E6: 現状の値 | F6: 判断
A7: フロントとバックの関係 | B7: 並列。両方とも ADOT が HEALTHY になってから起動 | C7: JBoss 同士は待たない | D7: フロントがバックの HEALTHY を待つ | E7: 依存なし | F7: 直列は300秒で足りない
A8: バックエンド startPeriod | B8: 160秒 | C8: 実測最大80秒 × 2 | D8: 160秒 | E8: 210秒 | F8: 見積そのもの
A9: フロント startPeriod | B9: 160秒 | C9: 自分の140秒と、検査が待つバックの160秒の長いほう | D9: 140秒。時計が後ろにずれる | E9: 210秒 | F9: 合成値にしない
A10: ADOT startPeriod / startTimeout | B10: 30秒 / 60秒 | C10: 未実測の計画値と、待ちの打ち切り | D10: 同じ | E10: 未提示 | F10: JBoss の160秒には足さない
A11: CloudWatch Agent startPeriod | B11: 30秒 | C11: プロセス確認。誰も待たない | D11: 同じ | E11: 未提示 | F11: コマンドはイメージ内に実在するもの
A12: ECS の猶予 | B12: 300秒 | C12: 見通し210秒、余り90秒 | D12: 420秒 | E12: 300秒 | F12: ALB の検査開始を遅らせる値ではない
A13: ALB interval / healthy / unhealthy | B13: 10 / 2 / 3 | C13: 平常時の切り離しは約30秒 | D13: 同じ | E13: 未提示 | F13: unhealthy を10にすると平常時も遅い
A15: 色の意味
A16: 色 | B16: 使う場所 | C16: 読み方
A17: 黒 | B17: 見出し。シート名と大見出し | C17: 文字は白
A18: 濃い灰 | B18: 列見出し | C18: 文字は白
A19: 中間の灰 | B19: 注記、推奨行の地 | C19: 強調は太字と左の太線。色相は変えない
A20: 薄い灰の入力セル | B20: 変えてよい実測と方針 | C20: 「計算」シートの C 列
A21: 白とごく薄い灰の縞 | B21: 本文 | C21: 1行おき
A23: 読み順
A24: 順 | B24: シート | C24: 内容
A25: 1 | B25: 結論 | C25: 推奨値と、300秒で起きること
A26: 2 | B26: 計算 | C26: 入力と、すべての秒数の式
A27: 3 | B27: バッファ内訳 | C27: 2倍の内側を秒で分解する
A28: 4 | B28: たとえ話 | C28: 学校の朝の準備で仕組みを見る
A29: 5 | B29: 時計の仕組み | C29: 誰がどの秒を数えるか
A30: 6 | B30: 指定できる値 | C30: API の上限と初期値
A31: 7 | B31: パターン比較 | C31: 現状、推奨、直列、合成、依存なし
A32: 8 | B32: 推奨設定 | C32: タスク定義に書く値とコマンド
A33: 9 | B33: タイムライン | C33: 時刻ごとの状態
A34: 10 | B34: 300秒の瞬間 | C34: 依頼文の場面を2つのパターンで並べる
A35: 11 | B35: 歴史 | C35: なぜこのタイマーが別々にできたか
... A37: 13 | B37: 用語 | C37: たとえと公式名の対応
A39: ワークスペースにタスク定義は無かった。現状値は依頼文に書かれていたものだけ。ADOT の30秒は実測ではなく計画値。JBoss の20〜80秒、15〜70秒は依頼文の実測として扱っている。

Sheet 計算
A1: 入力と計算 灰色が入力、白の数値は式
A2: C列の灰色を変えると、このシートの式と、他シートからの参照が変わる。式は最大実測×倍率、max、interval×閾値。
A4: 入力
A5: 項目 | B5: 名前 | C5: 値 | D5: 単位 | E5: 意味 | F5: 根拠
A6: バックエンド実測最小 | B6: back_min | C6: 20 | D6: 秒 | E6: 起動開始ログからデプロイ完了ログの最短 | F6: 依頼文
A7: バックエンド実測最大 | B7: back_max | C7: 80 | D7: 秒 | E7: 同じ区間の最長 | F7: 依頼文
A8: フロント実測最小 | B8: front_min | C8: 15 | D8: 秒 | E8: 同じ区間の最短 | F8: 依頼文
A9: フロント実測最大 | B9: front_max | C9: 70 | D9: 秒 | E9: 同じ区間の最長 | F9: 依頼文
A10: 見積倍率 | B10: multiplier | C10: 2 | D10: 倍 | E10: 最大実測を何倍にするか | F10: 依頼文の方針
A11: ADOT計画値 | B11: adot_plan | C11: 30 | D11: 秒 | E11: 13133が成功するまでの計画値。未実測 | F11: 仮定A1
A12: ADOTのstartTimeout | B12: adot_start_timeout | C12: 60 | D12: 秒 | E12: これを超えてHEALTHYにならなければ待っている側は起動しない | F12: Fargate上限120の内側
A13: バックinterval | B13: back_interval | C13: 15 | D13: 秒 | E13: バックエンドの検査間隔 | F13: 推奨
A14: フロントinterval | B14: front_interval | C14: 15 | D14: 秒 | E14: フロントの検査間隔 | F14: 推奨
A15: ADOT interval | B15: adot_interval | C15: 5 | D15: 秒 | E15: サイドカーは短くしてHEALTHYの観測を早くする | F15: API最小は5
A16: CW interval | B16: cw_interval | C16: 10 | D16: 秒 | E16: CloudWatch Agentの検査間隔 | F16: 推奨
A17: ALB interval | B17: alb_interval | C17: 10 | D17: 秒 | E17: ターゲットグループの検査間隔 | F17: 推奨
... A34: 現状バックstartPeriod | B34: current_back | C34: 210 | D34: 秒 | E34: 依頼文の現状 | F34: 依頼文
A36: 見積とバッファの式
A37: 項目 | B37: 名前 | C37: 値 | D37: 単位 | E37: 式の意味 | F37: セル
A38: バック見積 | B38: back_budget | C38: =C7*C10 | D38: 秒 | E38: 実測最大 × 倍率 | F38: C38
A39: フロント自身の見積 | B39: front_own | C39: =C9*C10 | D39: 秒 | E39: 実測最大 × 倍率 | F39: C39
A40: バックのバッファ | B40: back_buffer | C40: =C38-C7 | D40: 秒 | E40: 見積 − 実測最大。2倍なら実測最大と同じ | F40: C40
A41: フロントのバッファ | B41: front_buffer | C41: =C39-C9 | D41: 秒 | E41: 見積 − 実測最大 | F41: C41
A42: バック サンプル外 | B42: back_unseen | C42: =C40*C32 | D42: 秒 | E42: バッファ × 配分比率 | F42: C42
A43: フロント サンプル外 | B43: front_unseen | C43: =C41*C32 | D43: 秒 | E43: バッファ × 配分比率 | F43: C43
A44: バック 検査1回分 | B44: back_slot | C44: =C13 | D44: 秒 | E44: intervalを1回、バッファの中に割り当てる | F44: C44
A45: フロント 検査1回分 | B45: front_slot | C45: =C14 | D45: 秒 | E45: intervalを1回 | F45: C45
A46: バック ログのあと | B46: back_post | C46: =C40-C42-C44 | D46: 秒 | E46: バッファの残り。計測値ではない | F46: C46
A47: フロント ログのあと | B47: front_post | C47: =C41-C43-C45 | D47: 秒 | E47: バッファの残り。計測値ではない | F47: C47
A48: 実測最大の差 | B48: measured_gap | C48: =C7-C9 | D48: 秒 | E48: バック最大 − フロント最大 | F48: C48
A49: バッファの差 | B49: buffer_gap | C49: =C40-C41 | D49: 秒 | E49: バックのバッファ − フロントのバッファ | F49: C49
A50: 遅いほうに合わせる追加 | B50: slower_extra | C50: =C48+C49 | D50: 秒 | E50: フロント見積をバック見積まで伸ばす差分 | F50: C50
A51: パターンA フロントstartPeriod | B51: front_start_a | C51: =MAX(C39,C38) | D51: 秒 | E51: 自分の見積と相手の見積の長いほう | F51: C51
A52: パターンA バックstartPeriod | B52: back_start_a | C52: =C38 | D52: 秒 | E52: 自分の見積 | F52: C52
A53: 準備完了後の長いほう | B53: post_ready | C53: =MAX(C14,C18*C17) | D53: 秒 | E53: コンテナintervalと、ALB閾値×間隔の長いほう。同時に進むので足さない | F53: C53
A54: パターンA 準備完了 | B54: ready_a | C54: =C11+C51 | D54: 秒 | E54: ADOT計画値＋遅いほうの見積 | F54: C54
A55: パターンA 両方healthyの見通し | B55: both_a | C55: =C54+C53 | D55: 秒 | E55: 準備完了＋長いほう | F55: C55
A56: パターンA 猶予の余り | B56: margin_a | C56: =C20-C55 | D56: 秒 | E56: 猶予 − 見通し | F56: C56
A57: ADOTが60秒のときの見通し | B57: edge_both | C57: =C12+C38+C53 | D57: 秒 | E57: startTimeoutの端＋見積＋長いほう | F57: C57
A58: そのときの余り | B58: edge_margin | C58: =C20-C57 | D58: 秒 | E58: 猶予 − 端の見通し | F58: C58
...

Sheet バッファ内訳
A1: デプロイバッファの内訳 2倍の内側を秒にする
A2: 割り当ては方針の秒数を説明するために割ったもの。ログのあと25秒や20秒を、別のストップウォッチで測ったという意味ではない。
A4: バックエンド
A5: 区分 | B5: 秒 | C5: 計算 | D5: 何の時間か | E5: 参照
A6: 実測最小 | B6: =計算!C6 | C6: 入力 | D6: 起動開始ログからデプロイ完了ログの最短 | E6: 計算!C6
A7: 実測最大 | B7: =計算!C7 | C7: 入力 | D7: 同じ区間の最長。見積の土台 | E7: 計算!C7
A8: 実測の幅 | B8: =計算!C7-計算!C6 | C8: 最大−最小。この表では計算シートを参照 | D8: 20秒から80秒なら幅は60秒 | E8: 計算!C7-計算!C6
A9: バッファ合計 | B9: =計算!C40 | C9: 見積−実測最大 | D9: 倍率2なら、実測最大と同じ秒数 | E9: 計算!C40
A10: サンプル外の悪化 | B10: =計算!C42 | C10: バッファ×配分比率 | D10: 測った中の最悪よりさらに悪い分。CPUの分け合い、クラスロード、GC、成果物の増加 | E10: 計算!C42
A11: 検査1回分 | B11: =計算!C44 | C11: バックエンドのinterval | D11: 完了の直後に検査が外れたとき、次の検査までをバッファに含める | E11: 計算!C44
A12: ログのあと | B12: =計算!C46 | C12: バッファ−サンプル外−検査1回 | D12: デプロイ完了ログと、healthcheckが200を返す瞬間の差。割り当て | E12: 計算!C46
A13: 見積合計 = startPeriod | B13: =計算!C38 | C13: 実測最大＋バッファ | D13: バックエンドのstartPeriod | E13: 計算!C38
A15: フロントエンド自身
A16: 区分 | B16: 秒 | C16: 計算 | D16: 何の時間か | E16: 参照
A17: 実測最小 | B17: =計算!C8 | C17: 入力 | D17: 起動開始ログからデプロイ完了ログの最短 | E17: 計算!C8
A18: 実測最大 | B18: =計算!C9 | C18: 入力 | D18: 同じ区間の最長 | E18: 計算!C9
A19: 実測の幅 | B19: =計算!C9-計算!C8 | C19: 最大−最小 | D19: 15秒から70秒なら幅は55秒 | E19: 計算!C9-計算!C8
A20: バッファ合計 | B20: =計算!C41 | C20: 見積−実測最大 | D20: 倍率2なら実測最大と同じ | E20: 計算!C41
A21: サンプル外の悪化 | B21: =計算!C43 | C21: バッファ×配分比率 | D21: バックエンドと同じ割り当て方 | E21: 計算!C43
A22: 検査1回分 | B22: =計算!C45 | C22: フロントのinterval | D22: 次の検査までの1回 | E22: 計算!C45
A23: ログのあと | B23: =計算!C47 | C23: バッファの残り | D23: デプロイ完了ログから待受が応答するまでの割り当て | E23: 計算!C47
A24: 自分だけの見積 | B24: =計算!C39 | C24: 実測最大＋バッファ | D24: 検査が自分だけなら、この秒がstartPeriod | E24: 計算!C39
A26: パターンAでフロントが160秒になる追加分
A27: 区分 | B27: 秒 | C27: 計算 | D27: 何の時間か | E27: 参照
A28: 自分だけの見積 | B28: =計算!C39 | C28: 上の表の合計 | D28: フロントのログ区間の2倍 | E28: 計算!C39
A29: 実測最大の差 | B29: =計算!C48 | C29: バック最大−フロント最大 | D29: 80−70。新しいバッファではない | E29: 計算!C48
A30: バッファの差 | B30: =計算!C49 | C30: バックのバッファ−フロントのバッファ | D30: 80−70。2倍方針から出る差 | E30: 計算!C49
A31: 追加分 | B31: =計算!C50 | C31: 2つの差の和 | D31: 遅いほうに合わせるための20秒 | E31: 計算!C50
A32: フロント startPeriod | B32: =計算!C51 | C32: max(自分の見積, バックの見積) | D32: 検査が両方を見るので長いほう | E32: 計算!C51
A34: 猶予300秒の使い方
A35: 区分 | B35: 秒 | C35: 計算 | D35: 何の時間か | E35: 参照
A36: ADOT計画値 | B36: =計算!C11 | C36: 入力 | D36: アプリのstartPeriodの外。猶予の先頭には含まれる | E36: 計算!C11
A37: 遅いほうのJBoss見積 | B37: =計算!C51 | C37: max | D37: 実測最大とそのバッファ | E37: 計算!C51
A38: その後の長いほう | B38: =計算!C53 | C38: max(コンテナinterval, ALB回復) | D38: 同時に進む。足さない | E38: 計算!C53
A39: 見通し | B39: =計算!C55 | C39: 3つの和 | D39: 両方healthyの目安 | E39: 計算!C55
A40: 余り | B40: =計算!C56 | C40: 猶予−見通し | D40: 計画より遅いとき用 | E40: 計算!C56
A41: 猶予 | B41: =計算!C20 | C41: 入力 | D41: パターンAの推奨 | E41: 計算!C20
A42: ADOTが60秒のときの見通し | B42: =計算!C57 | C42: startTimeoutの端 | D42: 60を超えたらタスクは起動をあきらめる | E42: 計算!C57
A43: その余り | B43: =計算!C58 | C43: 猶予−端の見通し | D43: まだ正なら300秒のままでよい | E43: 計算!C58
A45: 直列420秒の使い方
...

Sheet 結論
A1: 結論
A2: フロントがバックの HEALTHY を待つと、300秒の時点でフロントは起動して約95秒。見積140秒まで45秒足りない。ALBは300秒で検査を始めるのではなく、登録直後から失敗している。300秒でスケジューラが無視をやめる。
A4: 推奨する値
A5: 対象 | B5: 項目 | C5: 値 | D5: 式 | E5: 意図
A6: ADOT Collector | B6: essential / dependsOn | C6: true / なし | D6: 固定 | E6: 最初に起動する。13133の検査を持つ
A7: ADOT Collector | B7: startTimeout | C7: =計算!C12 | D7: =計算!C12 | E7: Fargateで書ける上限は120秒
A8: ADOT Collector | B8: startPeriod / interval / timeout / retries | C8: 30 / 5 / 3 / 3 | D8: 計算!C30 ほか | E8: 失敗を数えない時間は計画値と同じ30秒
A9: CloudWatch Agent | B9: essential / dependsOn / startTimeout | C9: true / なし / 付けない | D9: 固定 | E9: 誰も待たないのでstartTimeoutは効かない
A10: CloudWatch Agent | B10: startPeriod / interval / timeout / retries | C10: 30 / 10 / 5 / 3 | D10: 計算!C31 ほか | E10: プロセス確認
A11: バックエンド | B11: dependsOn | C11: ADOTがHEALTHY | D11: 固定 | E11: トレースを受けられるようになってから起動
A12: バックエンド | B12: startTimeout | C12: 付けない | D12: 見積が120秒を超える | E12: 120と書くと正当な遅い起動を打ち切る
A13: バックエンド | B13: startPeriod | C13: =計算!C52 | D13: =計算!C38 | E13: 実測最大の2倍
A14: バックエンド | B14: interval / timeout / retries | C14: 15 / 5 / 3 | D14: 計算!C13 ほか | E14: 自分のhealthcheck
A15: フロントエンド | B15: dependsOn | C15: ADOTがHEALTHY。バックには依存しない | D15: 固定 | E15: 2つのJBossは同時に起動する
A16: フロントエンド | B16: startPeriod | C16: =計算!C51 | D16: =MAX(計算!C39,計算!C38) | E16: 検査がバックも見るので長いほう
A17: フロントエンド | B17: interval / timeout / retries | C17: 15 / 10 / 3 | D17: 計算!C14 ほか | E17: URLを2本見るのでtimeoutは10秒
A18: ECSサービス | B18: 猶予 | C18: =計算!C20 | D18: =計算!C20 | E18: 見通しは計算!C55、余りは計算!C56
A19: ALB | B19: interval / timeout / healthy / unhealthy | C19: 10 / 5 / 2 / 3 | D19: 計算!C17 ほか | E19: 起動中のunhealthyは猶予が無視する
A21: 300秒という数字が指し得るもの
A22: 名前 | B22: 設定場所 | C22: 今回の扱い | D22: 向き | E22: 初期値
A23: healthCheckGracePeriodSeconds | B23: ECSサービス | C23: 起動中にスケジューラが異常を無視する。推奨は300秒 | D23: 起動 | E23: 0秒
A24: startPeriod | B24: 各コンテナ | C24: 失敗回数を数えない。上限300秒。推奨は160秒または30秒 | D24: そのコンテナの起動 | E24: 0秒
A25: deregistration_delay.timeout_seconds | B25: ターゲットグループ | C25: 終了時の接続ドレイン。今回は変えない | D25: 停止 | E25: 300秒
A26: idle timeout | B26: ALB | C26: 通信の無い接続を閉じる。ヘルスチェックではない | D26: 通信中 | E26: 60秒
A27: startTimeout | B27: 待たれるコンテナ | C27: 依存の待ちの打ち切り。Fargateは2〜120秒 | D27: 起動順 | E27: 未指定の打ち切りはAPIに無い
A28: stopTimeout | B28: 各コンテナ | C28: SIGTERMからSIGKILLまで。起動の見積に足さない | D28: 停止 | E28: 30秒。上限120秒
A30: 直列を残すとき
A31: 時点 | B31: 秒 | C31: 意味
A32: フロント起動 | B32: =計算!C59 | C32: ADOT＋バック見積＋観測1回
A33: 猶予300秒のときの年齢 | B33: =計算!C60 | C33: まだ見積の途中
A34: 不足 | B34: =計算!C61 | C34: 正なら、300秒では見積に届いていない
A35: 両方healthyの見通し | B35: =計算!C63 | C35: この秒まで猶予が異常を無視する必要がある
A36: 直列の推奨猶予 | B36: =計算!C21 | C36: 見通しに余りを足した入力値
A37: その余り | B37: =計算!C64 | C37: 直列用
A39: startPeriodを短くしても、直列のフロント起動時刻は動かない。動くのは猶予を420秒にすることか、直列をやめること。FargateのstartTimeoutは120秒までなので、205秒前後の待ちを打ち切り秒数としては書けない。

Sheet たとえ話
A1: たとえ話 文化祭の教室
A2: 1つの教室が1つのFargateタスク。4人は同じ内線（localhost）を使う。廊下の先生はALB。校長はECSのサービススケジューラ。
A4: 教室の人 | B4: コンテナ | C4: 仕事 | D4: 対応する設定
A5: 図書係 | B5: ADOT Collector | C5: 来場者の行動メモを受け取る。席に着く前に渡されたメモは床に落ちる | D5: dependsOn HEALTHY。ポート13133
A6: 出席係 | B6: CloudWatch Agent | C6: 係が席にいるかを見る。料理の完成は見ない | D6: プロセス確認。誰もこの人を待たない
A7: 調理係 | B7: バックエンド JBoss | C7: 実測は20〜80秒。見積は一番遅かった時間の2倍で160秒 | D7: startPeriod 160秒
A8: 受付 | B8: フロントエンド JBoss | C8: 実測は15〜70秒。見積140秒。健康確認で調理係の窓口も見る | D8: startPeriodは長いほうの160秒
A9: 廊下の先生 | B9: ALB | C9: 名簿に載った瞬間から受付のドアを叩く。300秒待ってから叩き始めはしない | D9: interval 10秒、閾値2と3
A10: 校長 | B10: ECSサービススケジューラ | C10: 朝の300秒は、先生がダメと言っても教室を畳まない。過ぎたら畳む | D10: healthCheckGracePeriodSeconds
A11: 靴ひものカード | B11: startPeriod | C11: 結んでいるあいだは失敗を数えない。早く結べば残り時間を待たない | D11: 上限300秒
A12: あの人ができてから出る | B12: dependsOn HEALTHY | C12: 調理係の完了を待ってから受付が始めると、待ちは足し算になる | D12: パターンB
A14: 足し算と、遅いほう
A15: やり方 | B15: 待ち方 | C15: 時間の形 | D15: 結果
A16: 同時に始める | B16: 図書係が座ってから、調理と受付が一緒に始める | C16: 遅いほうの1人分 | D16: 推奨。見通しは計算シートの両方healthy
A17: 受付が調理を待つ | B17: 調理が終わってから受付が包丁を持つ | C17: 2人分の足し算 | D17: 300秒の時点で受付はまだ途中
A18: カードを短くする | B18: 靴ひもカードだけを短くする | C18: 人の動きは変わらない | D18: 正当な遅い起動を失敗扱いにする
A20: カード（startPeriod）は人を待たせるベルではない。早く準備できた人は、カードの残り時間があっても、その場で準備完了になる。

Sheet 時計の仕組み
A1: 時計の仕組み 誰が秒を数えるか
A2: タイマーは4つ以上あり、開始点も、異常のあとの行動も違う。1つの300秒では兼ねられない。
A4: 動作 | B4: 持ち主 | C4: 始まる時点 | D4: 終わるあとの行動
A5: イメージ取得とENI | B5: ECSとFargate | C5: タスク作成。PROVISIONINGからACTIVATING | D5: コンテナ起動の前。startPeriodの外
A6: ターゲット登録 | B6: ECS。状態はACTIVATING | C6: コンテナが仕事を始める前後 | D6: ALBが検査を始める
A7: 起動順 | B7: ECSエージェント | C7: dependsOnの条件が満たされたとき | D7: 条件の相手がHEALTHYになるまでプロセスを作らない
A8: 検査コマンド | B8: コンテナの中 | C8: 起動から約1 interval後が最初 | D8: 終了コード0なら成功
A9: 失敗を数えない | B9: startPeriod | C9: そのコンテナの起動 | D9: 成功した時点で終わり、その後の失敗は数える
A10: HEALTHYにする | B10: ECS | C10: 成功が1回出たとき | D10: dependsOnの相手は、ここで待っていた側を起動できる
A11: タスクをUNHEALTHY | B11: ECS | C11: essentialが1つでもUNHEALTHY | D11: 猶予の外ならスケジューラが止める
A12: タスクを止める判断 | B12: サービススケジューラ | C12: 猶予の終了後 | D12: ELB、VPC Lattice、コンテナ検査の異常を採用する
A13: トラフィック | B13: ALB | C13: ターゲットがhealthy | D13: 猶予はALBの判定を消さない
A14: トレース受信 | B14: ADOT | C14: パイプラインと13133の準備後 | D14: 準備前の送信は、アプリが再送しなければ落ちる
A16: タスクの健康が決まる順
A17: 順 | B17: 条件 | C17: タスクの健康 | D17: 注意
A18: 1 | B18: essentialが1つでもUNHEALTHY | C18: UNHEALTHY | D18: CloudWatch Agentもessentialなら、プロセス検査の失敗で全体が異常
A19: 2 | B19: 上でなく、essentialが1つでもUNKNOWN | C19: UNKNOWN | D19: 起動直後はここ。壊れているとはまだ限らない
A20: 3 | B20: 検査を持つessentialが全部HEALTHY | C20: HEALTHY | D20: 検査の無いコンテナはこの判定に入らない
A22: 猶予について文書が言っていること
A23: 文書 | B23: 言っていること | C23: 読み方 | D23: 扱い
A24: 開発者ガイド 2026-10-10 | B24: タスクが最初に開始されたあと、異常なELB、VPC Lattice、コンテナ検査を無視する | C24: 無視するのはスケジューラの停止判断 | D24: 契約としてこちらを優先
A25: 2017-12-27の告知 | B25: ELBの検査を、定められた時間無視する | C25: 当時の対象はELB | D25: 歴史。いまの文面は広い
A26: コンソールヘルプ | B26: ELBを無視し、RUNNING前に止めないため | C26: 開発者ガイドより狭い | D26: 開始点の特定には使わない
A27: ALBの仕様 | B27: 登録後に検査する。新規は成功1回でhealthy。戻るときは閾値 | C27: 猶予は検査を遅らせない | D27: 起動中にunhealthyになるのは想定内
A29: 開始点が状態名のどれかは、開発者ガイドの一文では特定できない。安全側では、ターゲット登録が済んだ時点で時計は動いているものとして秒数を置いている。イメージ取得の長さは、この300秒に含めていない。

Sheet 指定できる値
A1: 指定できる値 2026-10月のAPI
A2: 範囲を超える値はタスク定義またはサービス定義として登録できない。startPeriodの301秒は書けない。FargateのstartTimeoutの121秒も書けない。
A4: コンテナヘルスチェック
A5: 項目 | B5: 範囲 | C5: 初期値 | D5: 今回 | E5: 備考
A6: command | B6: CMDまたはCMD-SHELLで始まる配列 | C6: 必須 | D6: イメージ内に実在するコマンド | E6: 終了コード0が成功
A7: interval | B7: 5〜300秒 | C7: 30秒 | D7: ADOT 5、CW 10、JBoss 15 | E7: 最初の検査もおおよそこの間隔のあと
A8: timeout | B8: 2〜60秒 | C8: 5秒 | D8: ADOT 3、CW 5、バック5、フロント10 | E8: intervalより短くする
A9: retries | B9: 1〜10 | C9: 3 | D9: すべて3 | E9: startPeriodのあとの連続失敗回数
A10: startPeriod | B10: 0〜300秒 | C10: 0 | D10: ADOT 30、CW 30、JBoss 160 | E10: 成功すると残り時間を待たない
A12: dependsOn
A13: 条件 | B13: 意味 | C13: 今回 | D13: 制約 | E13: 備考
A14: START | B14: プロセスが起動したら進む | C14: ADOTには使わない | D14: ポートが開いた保証はない | E14: 公式のADOT手順例はこちら。トレースには弱い
A15: HEALTHY | B15: 検査が成功するまで待たせる | C15: アプリからADOTへ | D15: 相手にhealthCheckが必須 | E15: 確認はタスク起動時だけ
A16: COMPLETE | B16: 終了まで待つ | C16: 使わない | D16: essentialな相手には不可 | E16: 初期化コンテナ用
A17: SUCCESS | B17: 終了コード0まで待つ | C17: 使わない | D17: essentialな相手には不可 | E17: 初期化コンテナ用
A19: 時間の上限
A20: 項目 | B20: Fargateの範囲 | C20: 未指定 | D20: 今回 | E20: 理由
A21: startTimeout | B21: 2〜120秒 | C21: 打ち切り秒数はAPIに無い | D21: ADOTだけ60秒 | E21: バックの160秒は120秒に入らない
A22: stopTimeout | B22: 2〜120秒 | C22: 30秒 | D22: 今回の起動計算では変えない | E22: 停止の時計。起動に足さない
A23: healthCheckGracePeriodSeconds | B23: 0〜2147483647秒 | C23: 0秒 | D23: 並列は300、直列は420 | E23: サービスの項目。ALBの属性ではない
A24: ALB interval | B24: 5〜300秒 | C24: 30秒 | D24: 10秒 | E24: 戻る時間は閾値×間隔
A25: ALB timeout | B25: 2〜120秒 | C25: 5秒 | D25: 5秒 | E25: intervalより短くする
A26: ALB healthy閾値 | B26: 2〜10 | C26: 5 | D26: 2 | E26: 新規登録の初回は成功1回。戻るときだけ閾値
A27: ALB unhealthy閾値 | B27: 2〜10 | C27: 2 | D27: 3 | E27: 平常時の切り離し約30秒。10にすると平常時も約300秒
A28: deregistration_delay | B28: 0〜3600秒 | C28: 300秒 | D28: 変えない | E28: 終了時のドレイン。起動の300秒とは別
A30: プラットフォーム1.3.0は2026-06-15に新規起動ができなくなり、2026-06-30に残タスクが停止されている。dependsOnは2019-03-27以降のFargateで使え、いまは1.4.0以降を指定する。通常はLATEST。

Sheet パターン比較
A1: パターン比較
A2: 秒数は計算シートを参照する。推奨はパターンA。パターンBは依頼文の直列。パターンCは現状の210秒の読み方の一つ。
A4: 項目 | B4: 0 現状 | C4: A 推奨 | D4: B 直列 | E4: C バックだけADOT待ち | F4: D 依存なし | G4: 見方
A5: フロントの依存 | B5: なし | C5: ADOTがHEALTHY | D5: バックがHEALTHY | E5: なし | F5: なし | G5: AはJBoss同士を待たない
A6: バックの依存 | B6: なし | C6: ADOTがHEALTHY | D6: ADOTがHEALTHY | E6: ADOTがHEALTHY | F6: なし | G6: トレースの条件はA、B、C
A7: フロントstartPeriod | B7: =計算!C33 | C7: =計算!C51 | D7: =計算!C39 | E7: =計算!C33 | F7: =計算!C51 | G7: Bは時計が後ろなので自分の見積でよい
A8: バックstartPeriod | B8: =計算!C34 | C8: =計算!C52 | D8: =計算!C52 | E8: =計算!C52 | F8: =計算!C52 | G8: 現状210は見積160より長い
A9: ADOT startPeriod | B9: 未提示 | C9: =計算!C30 | D9: =計算!C30 | E9: =計算!C30 | F9: =計算!C30 | G9: 計画値
A10: CW startPeriod | B10: 未提示 | C10: =計算!C31 | D10: =計算!C31 | E10: =計算!C31 | F10: =計算!C31 | G10: 誰も待たない
A11: startTimeout | B11: 未提示 | C11: ADOTに60秒 | D11: ADOTに60秒。バックには付けられない | E11: ADOTに60秒 | F11: なし | G11: Fargate上限120秒
A12: 猶予 | B12: =計算!C20 | C12: =計算!C20 | D12: =計算!C21 | E12: =計算!C20 | F12: =計算!C20 | G12: Bだけ420秒
A13: 両方healthyの見通し | B13: ADOT待ちが無いのでより短い | C13: =計算!C55 | D13: =計算!C63 | E13: =計算!C55 | F13: ADOTをパスに含まない | G13: AとCは同じ見通し
A14: 300秒時点 | B14: 提示値の範囲では収まる | C14: 既にhealthyの見通し | D14: フロント年齢が見積未満 | E14: Aと同じく収まる | F14: 収まる。トレースは落ち得る | G14: Bだけが依頼文の衝突
A15: 停止順 | B15: 決まらない | C15: アプリのあとADOT | D15: フロント、バック、ADOT | E15: バックのあとADOT。フロントは不定 | F15: 決まらない | G15: 起動の逆順
A16: 採用 | B16: トレースの条件を満たさない | C16: 採用する | D16: 300秒では不成立 | E16: 秒数は成立。式が合成になる | F16: トレースの条件を満たさない | G16: Aを推奨
A18: パターンCの現状210秒は、ADOT計画値＋バック見積＋余り、と算術が一致する。一致は、その意図で210が選ばれた証拠ではない。余りは計算!C75。
A20: パターンCの210秒の分解
A21: 区分 | B21: 秒 | C21: 参照
A22: フロント実測最大 | B22: =計算!C9 | C22: 計算!C9
A23: フロントのバッファ | B23: =計算!C41 | C23: 計算!C41
A24: 遅いほうへの追加 | B24: =計算!C50 | C24: 計算!C50
A25: ADOT計画値 | B25: =計算!C11 | C25: フロントの時計に含まれる
A26: 合計の最短 | B26: =計算!C74 | C26: 計算!C74
A27: 現状210との余り | B27: =計算!C75 | C27: 設計意図としては未確認

Sheet 推奨設定
A1: 推奨設定 パターンAをタスク定義の形にする
A2: essentialは依頼どおりすべてtrue。1つがUNHEALTHYならタスク全体がUNHEALTHYになる。検査コマンドがイメージに無いと、デプロイがHEALTHYに到達しない。
A4: コンテナ | B4: essential | C4: dependsOn | D4: startTimeout | E4: interval | F4: timeout | G4: retries | H4: startPeriod | I4: command
A5: adot-collector | B5: true | C5: なし | D5: 60 | E5: 5 | F5: 3 | G5: 3 | H5: 30 | I5: CMD /healthcheck
A6: cloudwatch-agent | B6: true | C6: なし | D6: 未設定 | E6: 10 | F6: 5 | G6: 3 | H6: 30 | I6: CMD-SHELL pidof amazon-cloudwatch-agent || exit 1
A7: backend | B7: true | C7: adot-collector = HEALTHY | D7: 未設定 | E7: 15 | F7: 5 | G7: 3 | H7: =計算!C52 | I7: 自分の https://127.0.0.1:18080/iwinmichl/healthcheck
A8: frontend | B8: true | C8: adot-collector = HEALTHY | D8: 未設定 | E8: 15 | F8: 10 | G8: 3 | H8: =計算!C51 | I8: 自分の待受と、バックエンドの同じURLの両方
A10: コマンドの文
A11: コンテナ | B11: 文
A12: backend | B12: CMD-SHELL, curl -fsS --max-time 4 -k https://127.0.0.1:18080/iwinmichl/healthcheck || exit 1
A13: frontend | B13: CMD-SHELL, curl -fsS --max-time 4 -k https://127.0.0.1:<フロント待受>/<フロントの準備完了パス> && curl -fsS --max-time 4 -k https://127.0.0.1:18080/iwinmichl/healthcheck || exit 1
A14: adot | B14: CMD, /healthcheck コレクタ設定の health_check 拡張を 127.0.0.1:13133 で有効にする
A15: cloudwatch | B15: pidof がイメージに無ければ、そのイメージに実在するプロセス確認へ替える。検査を外すとタスク健康の判定から外れる
A17: ALBとサービス
A18: 項目 | B18: 値 | C18: 範囲 | D18: 理由
A19: HealthCheckIntervalSeconds | B19: 10 | C19: 5〜300 | D19: 戻る時間を短くする。平常時の検知も早くする
A20: HealthCheckTimeoutSeconds | B20: 5 | C20: 2〜120、interval未満 | D20: 初期値のまま
A21: HealthyThresholdCount | B21: 2 | C21: 2〜10 | D21: unhealthyから戻る連続成功。新規の初回は1回だが、起動中にunhealthyになるので戻る側が効く
A22: UnhealthyThresholdCount | B22: 3 | C22: 2〜10 | D22: 約30秒で切り離す。10にすると平常時の切り離しも長くなる
A23: Matcher | B23: 200 | C23: 200〜499 | D23: 準備完了だけを成功にする
A24: healthCheckGracePeriodSeconds | B24: =計算!C20 | C24: 0〜2147483647 | D24: 見通しは計算シートの両方healthy。余りもそこにある
A25: deregistration_delay | B25: 変えない（初期値300） | C25: 0〜3600 | D25: 停止側の時計。起動の修正では触らない
A26: stopTimeout | B26: 変えない（初期値30） | C26: 2〜120 | D26: JBossの停止を測ってから別途決める。160秒とは足さない
A28: -k は、証明書の名前が127.0.0.1と一致しないタスク内部の検査のため。外向けのTLS検証を外す設定ではない。検証できる証明書があるなら -k は付けない。フロントの待受ポートと準備完了パスは依頼文に無いので、ALBが叩く口と揃える。

Sheet タイムライン
A1: タイムライン 時刻0は依存のないコンテナの起動
A2: イメージ取得の長さは含まない。時刻は計算シートの式。ADOT計画値を変えると、この表の時刻も変わる。
A4: パターンA
A5: 出来事 | B5: 時刻（秒） | C5: バックエンド | D5: フロントエンド
A6: ADOTとCWが起動 | B6: 0 | C6: まだ起動しない | D6: まだ起動しない
A7: ADOTがHEALTHYの計画 | B7: =計算!C11 | C7: 起動する。startPeriodが始まる | D7: 同時に起動する。startPeriodが始まる
A8: ALBがunhealthyの目安 | B8: =計算!C65 | C8: 起動の途中 | D8: 起動の途中。トラフィックは流れない
A9: 遅いほうが準備完了 | B9: =計算!C54 | C9: 見積の終わり | D9: 自分のデプロイはもっと前に終わっている。200は相手を待つ
A10: コンテナHEALTHYの目安 | B10: =計算!C54+計算!C14 | C10: 検査1回分のあと | D10: 同じ
A11: 両方healthyの見通し | B11: =計算!C55 | C11: デプロイが数えてよい | D11: ALBも戻っている見通し
A12: コンテナ異常確定の目安 | B12: =計算!C71 | C12: ずっと失敗した場合だけ | D12: 同じ頃。猶予はまだ無視する
A13: 猶予の終わり | B13: =計算!C20 | C13: 既にHEALTHYなら残る | D13: 既にHEALTHYなら残る
A15: パターンB
A16: 出来事 | B16: 時刻（秒） | C16: バックエンド | D16: フロントエンド
A17: ADOTとCWが起動 | B17: 0 | C17: まだ起動しない | D17: 起動しない
A18: バックが起動 | B18: =計算!C11 | C18: startPeriod開始 | D18: まだ起動しない
A19: ALBがunhealthyの目安 | B19: =計算!C65 | C19: 起動の途中 | D19: 受付が居ないので失敗が続く
A20: バックがHEALTHYと観測 | B20: =計算!C59 | C20: 待っていた側を解放する | D20: ここで初めて起動。年齢0秒
A21: 猶予300秒 | B21: =計算!C20 | C21: HEALTHYのまま | D21: 年齢は計算!C60。不足は計算!C61
A22: フロント準備完了 | B22: =計算!C62 | C22: 既にサービス中 | D22: 自分の見積の終わり
A23: 両方healthy | B23: =計算!C63 | C23: 両方そろった見通し | D23: 猶予が420秒なら、この前に無視が終わらない
A24: 直列の猶予の終わり | B24: =計算!C21 | C24: 残りは計算!C64 | D24: ここで初めて無視が終わる
A26: パターンBの「猶予300秒」の行が、依頼文の場面。フロントの年齢が自分の見積より小さいあいだに、スケジューラがALBの異常を採用する。

Sheet 300秒の瞬間
A1: 300秒の瞬間
A2: 同じ300秒でも、並列と直列で教室の中の様子が違う。秒数は計算シートの入力に従う。
A4: 見ているもの | B4: パターンA 並列 | C4: パターンB 直列
A5: バックエンド | B5: 起動から約160秒の見積を、ADOTのあとに終えている | C5: もっと前にHEALTHY
A6: バックが動き始めてからの経過 | B6: =計算!C20-計算!C11 | C6: =計算!C20-計算!C11
A7: フロントの年齢 | B7: =計算!C20-計算!C11 | C7: =計算!C60
A8: フロントの見積 | B8: =計算!C51 | C8: =計算!C39
A9: 見積までの残り | B9: =計算!C51-(計算!C20-計算!C11) | C9: =計算!C61
A10: 残りが負なら | B10: 見積の時刻は過ぎている。300秒より前にhealthyの見通し | C10: 正なら、まだ見積の途中
A11: ALB | B11: 戻ったあとのhealthyの見通し。時刻は計算!C55 | C11: 登録直後から失敗し、約計算!C65秒でunhealthyのまま
A12: スケジューラ | B12: 無視を終える。既にhealthyなら止めない | C12: 無視を終える。unhealthyなので止める
A13: 依頼文の絵 | B13: 起きない。フロントはADOTの時点で起動済み | C13: 結果は起きる。検査の開始が300秒、という部分だけが違う
A15: 「残り」が負なのは、300秒の時点で見積時間を使い切ったあと、という表示。異常ではない。直列の残りが正なら、見積が終わっていない。
A17: 直列の300秒を文章にすると
A18: 順序 | B18: 内容
A19: 1 | B19: 時刻0にADOTとCloudWatch Agentが起動し、ALBはフロントのポートを叩き始める
A20: 2 | B20: ADOT計画値のあとバックエンドが起動する
A21: 3 | B21: バックエンドの見積と、検査1回分のあとにHEALTHYになり、フロントが初めて起動する
A22: 4 | B22: その起動時刻は計算シートの「直列でフロントが起動する時刻」
A23: 5 | B23: 猶予の終わりまでの年齢が、フロント自身の見積より小さい
A24: 6 | B24: ALBは新しい検査を始めるのではなく、すでにunhealthy
A25: 7 | B25: スケジューラは異常を採用し、タスクを止める

Sheet 歴史
A1: 歴史 なぜタイマーが分かれたか
A2: 起動が遅いJBossでは、別の時代に別の理由で増えたタイマーが同時に動く。
A4: 時期 | B4: できたもの | C4: 必要になった理由
A5: 2009年ごろ | B5: ELBが後ろのサーバを定期的に叩く | C5: 止まったサーバへ利用者を案内しないため
A6: 2015年 | B6: Amazon ECSの一般提供 | C6: サービスの健康は主にELBの結果だった
A7: 2016年7月 | B7: Docker 1.12のHEALTHCHECK | C7: ロードバランサーが無いプロセスも生死を返したくなった
A8: 2016年 | B8: Application Load Balancer | C8: パスとステータスコードで検査したくなった
A9: 2017-05-04 | B9: Docker 17.05のstart-period | C9: 起動中の失敗で異常にしたくない。成功したら猶予は終わる
A10: 2017年11月 | B10: AWS Fargate | C10: サーバを持たずにタスクを動かす
A11: 2017-12-27 | B11: ECSのELB猶予期間 | C11: 起動が遅いタスクをELBの失敗だけで止めていた
A12: 2018-03-08 | B12: ECSのコンテナヘルスチェック | C12: ELBが無くてもessentialコンテナの検査で置き換える
A13: 2019-03-07 | B13: dependsOn、startTimeout、stopTimeout | C13: 同じタスクの起動順と停止順を指定できなかった
A14: 2019-03-27 | B14: Fargateがそのパラメータに対応 | C14: テレメトリのサイドカーを先に上げ、停止は後にする
A15: 2020年 | B15: AWS Distro for OpenTelemetry | C15: 起動直後のトレースを、受信側がいないあいだ落とさないため
... A20: 2026-10の開発者ガイド | B20: 猶予の対象にELB、VPC Lattice、コンテナ検査 | C20: 2017年の告知はELBだけだった
A22: 告知の日付はAWS What's NewとDockerのリリースノートで確認したもの。ADOTは年だけを書き、日まではこの資料では特定していない。

Sheet 確認と出典
A1: 未確定と、次に確認すること
A2: この資料は稼働中のタスク定義を見ていない。次の確認で仮定が崩れたら、崩れた項目だけを計算シートで置き換える。
A4: 番号 | B4: 見ること | C4: 崩れたときの直し方
A5: 1 | B5: フロントの検査コマンドが、バックエンドのURLだけか | C5: 自分の待受が含まれていなければ、推奨コマンドの2本目を足す
A6: 2 | B6: バックエンド自身にヘルスチェックがあるか | C6: 無いとHEALTHY依存は定義できない
A7: 3 | B7: ADOTの設定にhealth_check拡張があり、13133と/healthcheckが一致するか | C7: 一致しないとHEALTHYにならない
A8: 4 | B8: CloudWatch Agentの検査コマンドがイメージに存在するか | C8: 存在しないとタスクがHEALTHYにならない
A9: 5 | B9: サービスの猶予と、ターゲットグループのderegistration_delayを別々に読む | C9: 同じ300秒でも項目が違う
A10: 6 | B10: バックエンドのポートを閉じたままフロントがデプロイ完了するか | C10: 完了しないなら直列にし、猶予は計算!C21
A11: 7 | B11: 1回のデプロイで、ACTIVATING、RUNNING、ADOT成功、両JBossのログ、ターゲットの状態の時刻を残す | C11: ADOTが30秒を超えたら計算!C11だけを変える。JBossの160秒には足さない
A12: 8 | B12: 実測最大が80秒または70秒を超えるか | C12: 超えたら計算!C7または計算!C9を変え、2倍は式が取り直す
A13: 9 | B13: 猶予中にコンテナがUNHEALTHYでもタスクが残り、猶予後に止まるか | C13: 開発者ガイドとコンソールヘルプの差を、そのサービスで確認する
A15: まだ特定していないこと
A16: 項目 | B16: 内容 | C16: 扱い
A17: 猶予の開始点 | B17: 「タスクが最初に開始されたあと」と、コンソールの「RUNNING前」が並立している | C17: 安全側で、登録後は時計が動いているものとして計算
A18: ADOTの実測 | B18: 30秒は計画値 | C18: 計算!C11
A19: フロントが相手不在で起動完了できるか | B19: 仮定A3 | C19: 手順6
A20: 実測時にサイドカーが居たか | B20: 依頼文では不明 | C20: 居なければ、バッファのサンプル外がその分をまだ見ていない
A21: startTimeout未指定の待ち | B21: Fargateの打ち切り秒数はAPIに無い | C21: だからバックエンドには書かず、ADOTに60秒を書く
A23: 出典
A24: 文書 | B24: 場所 | C24: 使った箇所
A25: ECS HealthCheck API | B25: docs.aws.amazon.com ECS API Reference API_HealthCheck | C25: 0〜300秒、成功するとretriesに入る
A26: ContainerDefinition | B26: API_ContainerDefinition | C26: startTimeoutとstopTimeoutはFargateで2〜120秒
A27: ContainerDependency | B27: API_ContainerDependency | C27: HEALTHYは起動時だけ
A28: Service definition parameters | B28: 開発者ガイド。参照時の更新表示2026-10-10 | C28: 猶予の無視対象
A29: Task lifecycle | B29: 開発者ガイド。参照時2026-10-09 | C29: ACTIVATINGでターゲット登録
A30: Optimize load balancer health checks | B30: ECS開発者ガイド | C30: 新規は成功1回。戻る時間は間隔×閾値
A31: ALB target group health checks | B31: ELBユーザーガイド。参照時2026-10-10 | C31: interval、timeout、閾値の範囲
A32: Fargate task networking | B32: ECS開発者ガイド | C32: 同一タスクのlocalhost
A33: What's New 2017-12-27 | B33: ELB Health Check Grace Period | C33: 猶予の登場
A34: What's New 2018-03-08 | B34: Container health checks | C34: コンテナ検査の登場
A35: What's New 2019-03-07 | B35: Container dependency management | C35: dependsOnの登場
... A39: OTel health_check拡張 | B39: collector-contrib README | C39: 初期エンドポイント13133

Sheet 用語
A1: 用語 たとえと公式名
A3: 公式名 | B3: たとえ | C3: 一文
A4: タスク | B4: 教室 | C4: Fargate上の1つの実行単位。コンテナは同じENIとlocalhostを共有する
A5: essential | B5: 欠けると教室が成立しない人 | C5: trueの人がUNHEALTHYならタスクがUNHEALTHY
A6: startPeriod | B6: 靴ひものカード | C6: 起動直後の失敗を回数に入れない。成功したら終わる。0〜300秒
A7: interval | B7: 先生がドアを叩く間隔 | C7: コンテナは5〜300秒。ALBも5〜300秒
A8: timeout | B8: 1回のノックを待つ時間 | C8: コンテナは2〜60秒。ALBは2〜120秒
A9: retries | B9: 連続して失敗してよい回数 | C9: startPeriodのあと。1〜10。初期値3
A10: dependsOn HEALTHY | B10: 相手の準備ができてから自分が出る | C10: 相手の検査成功までプロセスを起動しない
A11: startTimeout | B11: 待ちくたびれたら帰る | C11: Fargateは2〜120秒。未指定の打ち切りは文書に無い
A12: stopTimeout | B12: 片付けの制限時間 | C12: SIGTERMのあとSIGKILL。初期値30秒。上限120秒
A13: healthCheckGracePeriodSeconds | B13: 校長が朝のうちは見逃す時間 | C13: スケジューラが異常を無視する。検査自体は止まらない
A14: ACTIVATING | B14: 教室の鍵と名簿の準備 | C14: イメージ取得、コンテナ作成、ターゲット登録がこの状態に書かれている
... A23: localhost | B23: 教室内線 | C23: 同じタスクの別コンテナのポートに届く
